# Error Handling

> Remember that any given stream can only error out once!

## Subscribe error handling callback
Default error handling behavior covers by passing error handling callback as a second parameter to
``` subscribe ``` method.

```javascript
import { Subject } from 'rxjs';

const s$ = new Subject();

s$.subscribe(
    () => console.log('Success callback'),
    () => console.log('Error callback'),
    () => console.log('Complete callback')
);

s$.error();
s$.next(); // This emit won't fire any notification
```

In this case error notification will be catched by the second callbasck logs `Error callback`
message

After error was handled no `next()` method will not notify subscribers as well as `complete` callback won't be called.

## [catchError](https://rxjs-dev.firebaseapp.com/api/operators/catchError) operator

![catchError](https://rxjs-dev.firebaseapp.com/assets/images/marble-diagrams/catch.png "catchError marble")

> Catches errors on the observable to be handled by returning a new observable or throwing an error.

Error won't be kicked in until stream is not fired error.

But at the moment when you call `stream$.error()` `catchError` will be called and returned stream will stand instead of catched.

```javascript
import { Subject } from "rxjs";
import { catchError } from 'rxjs/operators';

const s$ = new Subject();
const s2$ = new Subject();

s$.pipe(
    catchError((err, caught) => {
        console.log(err); // <subject error 1>
        return s2$;
    })
).subscribe(
    str => console.log(`Success callback ${str}`), // Success callback <subject 2>
    () => console.log('Error callback'),
    () => console.log('Complete callback')
);

s$.error('<subject error 1>');
s$.next('<subject 1>');

s2$.next('<subject 2>');
```

## [throwError](https://rxjs-dev.firebaseapp.com/api/index/function/throwError)

![throwError](https://rxjs-dev.firebaseapp.com/assets/images/marble-diagrams/throw.png "throwError marble")

If you want to pass error down to the next catch function - you need to rethrow error with `throwError` operator;

```javascript
import { Subject, throwError } from "rxjs";
import { catchError } from 'rxjs/operators';

const s$ = new Subject();

s$.pipe(
    catchError((err, caught) => {
        console.log(err); // <subject error 1>
        return throwError(err);
    })
).subscribe(
    () => console.log('Success callback'), // won't be called
    err => console.log(`Error callback ${err}`), // will be called after catchError operator processing with `Error callback <subject error 1>` output
    () => console.log('Complete callback')
);

s$.error('<subject error 1>');
s$.next('<subject 1>');
```

## [finalize](https://rxjs-dev.firebaseapp.com/api/operators/finalize)

> Returns an Observable that mirrors the source Observable, but will call a specified function when the source terminates on complete or error.

As language has try/catch/finally construction as rxjs has `finalize` operator that will finalize the whole process till completion of error chain or stream at all.

```javascript
const s$ = new Subject();

s$.pipe(
    catchError((err, caught) => {
        console.log(err); // <subject error 1>
        return throwErrofor(err);
    }),
    finalize(() => console.log('Finally')) // Will be called at last
).subscribe(
    () => console.log('Success callback'), // won't be called
    err => console.log(`Error callback ${err}`), // will be called after catchError operator processing with `Error callback <subject error 1>` output
    () => console.log('Complete callback')
);

s$.error('<subject error 1>');
s$.next('<subject 1>');
```